Workbook
Name gvhd: [1]Sheet1!$B$4:$E$1500

Sheet DSSV-Tên đề tài-Hướng dẫn
A1: Thứ tự | B1: Mã sinh viên | C1: Họ đệm | D1: Tên | E1: Ngày sinh | F1: Giới tính | G1: Lớp hành chính | H1: Ngành/Chương trình đào tạo | I1: Mã học phần | J1: Khóa học | K1: Tên đề tài | L1: Đơn vị quản lý sinh viên | M1: Tên nhóm | N1: Người hướng dẫn | O1: Học hàm - Học vị | P1: Người hướng dẫn 2 | Q1: Học hàm - Học vị | R1: Ghi chú | S1: Tên đề tài (Tiếng Anh) | T1: Từ khóa (Tiếng Việt) | U1: Từ khóa (Tiếng Anh) | V1: Tóm tắt đồ án, khóa luận tốt nghiệp (Tiếng Việt) | W1: Tóm tắt đồ án, khóa luận tốt nghiệp (Tiếng Anh) | X1: Mã lớp MH/HP
A2: 1 | B2: 2019604777 | C2: Lê Việt | D2: Hoàng | E2: 36901 | F2: Nam | G2: 2019DHDTTT05 | H2: Công nghệ kỹ thuật điện tử - viễn thông | I2: FE6010 | J2: K14 | L2: Khoa Điện tử | M2: 1 | N2: Nguyễn Anh Dũng | R2: Thiếu tên đề tài | X2: 20234FE6010001
A3: 2 | B3: 2020601541 | C3: Trần Việt | D3: Hưng | E3: 37489 | F3: Nam | G3: 2020DHDTTT02 | H3: Công nghệ kỹ thuật điện tử - viễn thông | I3: FE6010 | J3: K15 | L3: Khoa Điện tử | M3: 1 | N3: Nguyễn Anh Dũng | R3: Thiếu tên đề tài | X3: 20234FE6010001
A4: 3 | B4: 2020606814 | C4: Phạm Ngọc | D4: Phương | E4: 37551 | F4: Nam | G4: 2020DHDTTT07 | H4: Công nghệ kỹ thuật điện tử - viễn thông | I4: FE6010 | J4: K15 | L4: Khoa Điện tử | M4: 1 | N4: Nguyễn Anh Dũng | R4: Thiếu tên đề tài | X4: 20234FE6010001
A5: 4 | B5: 2020603968 | C5: Nguyễn Đắc | D5: Bình | E5: 37432 | F5: Nam | G5: 2020DHDTTT04 | H5: Công nghệ kỹ thuật điện tử - viễn thông | I5: FE6010 | J5: K15 | K5: Thiết kế mô hình hệ thống điều khiển và giám sát các thiết bị điện trong gia đình | L5: Khoa Điện tử | M5: 2 | N5: Phạm Xuân Thành | X5: 20234FE6010001
A6: 5 | B6: 2020608060 | C6: Trịnh Xuân | D6: Hoàng | E6: 37422 | F6: Nam | G6: 2020DHDTTT04 | H6: Công nghệ kỹ thuật điện tử - viễn thông | I6: FE6010 | J6: K15 | K6: Thiết kế mô hình hệ thống điều khiển và giám sát các thiết bị điện trong gia đình | L6: Khoa Điện tử | M6: 2 | N6: Phạm Xuân Thành | X6: 20234FE6010001
A7: 6 | B7: 2020603850 | C7: Nguyễn Thế | D7: Huy | E7: 37494 | F7: Nam | G7: 2020DHDTTT04 | H7: Công nghệ kỹ thuật điện tử - viễn thông | I7: FE6010 | J7: K15 | K7: Thiết kế mô hình hệ thống điều khiển và giám sát các thiết bị điện trong gia đình | L7: Khoa Điện tử | M7: 2 | N7: Phạm Xuân Thành | X7: 20234FE6010001
A8: 7 | B8: 2020603046 | C8: Nguyễn Minh | D8: Đức | E8: 37287 | F8: Nam | G8: 2020DHDTTT03 | H8: Công nghệ kỹ thuật điện tử - viễn thông | I8: FE6010 | J8: K15 | K8: Nghiên cứu, thiết kế hệ thống phân loại sản phẩm có giám sát tốc độ và vị trí sử dụng PLC | L8: Khoa Điện tử | M8: 3 | N8: Nguyễn Thanh Hà | X8: 20234FE6010001
A9: 8 | B9: 2020603012 | C9: Vũ Đức | D9: Hoan | E9: 37282 | F9: Nam | G9: 2020DHDTTT03 | H9: Công nghệ kỹ thuật điện tử - viễn thông | I9: FE6010 | J9: K15 | K9: Nghiên cứu, thiết kế hệ thống phân loại sản phẩm có giám sát tốc độ và vị trí sử dụng PLC | L9: Khoa Điện tử | M9: 3 | N9: Nguyễn Thanh Hà | X9: 20234FE6010001
A10: 9 | B10: 2020603052 | C10: Ngô Ngọc | D10: Kiên | E10: 37590 | F10: Nam | G10: 2020DHDTTT03 | H10: Công nghệ kỹ thuật điện tử - viễn thông | I10: FE6010 | J10: K15 | K10: Nghiên cứu, thiết kế hệ thống phân loại sản phẩm có giám sát tốc độ và vị trí sử dụng PLC | L10: Khoa Điện tử | M10: 3 | N10: Nguyễn Thanh Hà | X10: 20234FE6010001
A11: 10 | B11: 2020604627 | C11: Lê Duy | D11: Đức | E11: 37470 | F11: Nam | G11: 2020DHDTTT05 | H11: Công nghệ kỹ thuật điện tử - viễn thông | I11: FE6010 | J11: K15 | K11: Thiết kế mô hình điều khiển và giám sát các thiết bị điện trong nhà bằng Wifi sử dụng ESP32 | L11: Khoa Điện tử | M11: 4 | N11: Nguyễn Tiến Kiệm | R11: Tên đề tài do SV đề xuất. Không phù hợp do dùng ESP32 | X11: 20234FE6010001
A12: 11 | B12: 2020604636 | C12: Nguyễn Xuân | D12: Sang | E12: 37277 | F12: Nam | G12: 2020DHDTTT05 | H12: Công nghệ kỹ thuật điện tử - viễn thông | I12: FE6010 | J12: K15 | K12: Thiết kế mô hình điều khiển và giám sát các thiết bị điện trong nhà bằng Wifi sử dụng ESP32 | L12: Khoa Điện tử | M12: 4 | N12: Nguyễn Tiến Kiệm | R12: Tên đề tài do SV đề xuất. Không phù hợp do dùng ESP32 | X12: 20234FE6010001
A13: 12 | B13: 2020604773 | C13: Nguyễn Trung | D13: Vĩnh | E13: 37375 | F13: Nam | G13: 2020DHDTTT05 | H13: Công nghệ kỹ thuật điện tử - viễn thông | I13: FE6010 | J13: K15 | K13: Thiết kế mô hình điều khiển và giám sát các thiết bị điện trong nhà bằng Wifi sử dụng ESP32 | L13: Khoa Điện tử | M13: 4 | N13: Nguyễn Tiến Kiệm | R13: Tên đề tài do SV đề xuất. Không phù hợp do dùng ESP32 | X13: 20234FE6010001
A14: 13 | B14: 2020601065 | C14: Nguyễn Xuân | D14: Chiến | E14: 37533 | F14: Nam | G14: 2020DHDTTT01 | H14: Công nghệ kỹ thuật điện tử - viễn thông | I14: FE6010 | J14: K15 | K14: Thiết kế hệ thống điều khiển thiết bị điện qua website. | L14: Khoa Điện tử | M14: 5 | N14: Nguyễn Tiến Kiệm | X14: 20234FE6010001
A15: 14 | B15: 2020601023 | C15: Xuân Quang | D15: Duy | E15: 37557 | F15: Nam | G15: 2020DHDTTT01 | H15: Công nghệ kỹ thuật điện tử - viễn thông | I15: FE6010 | J15: K15 | K15: Thiết kế hệ thống điều khiển thiết bị điện qua website. | L15: Khoa Điện tử | M15: 5 | N15: Nguyễn Tiến Kiệm | X15: 20234FE6010001
A16: 15 | B16: 2020608012 | C16: Đỗ Văn | D16: Nhất | E16: 37215 | F16: Nam | G16: 2020DHDTTT04 | H16: Công nghệ kỹ thuật điện tử - viễn thông | I16: FE6010 | J16: K15 | K16: Thiết kế hệ thống điều khiển thiết bị điện qua website. | L16: Khoa Điện tử | M16: 5 | N16: Nguyễn Tiến Kiệm | X16: 20234FE6010001
A17: 16 | B17: 2020606039 | C17: Hoàng Văn | D17: Giáp | E17: 36913 | F17: Nam | G17: 2020DHDTTT07 | H17: Công nghệ kỹ thuật điện tử - viễn thông | I17: FE6010 | J17: K15 | K17: Thiêt kế mô hình bãi đỗ xe thông minh | L17: Khoa Điện tử | M17: 6 | N17: Đỗ Thị Ngọc Ánh | X17: 20234FE6010001
A18: 17 | B18: 2020606137 | C18: Hoàng Đình | D18: Hiển | E18: 37550 | F18: Nam | G18: 2020DHDTTT07 | H18: Công nghệ kỹ thuật điện tử - viễn thông | I18: FE6010 | J18: K15 | K18: Thiêt kế mô hình bãi đỗ xe thông minh | L18: Khoa Điện tử | M18: 6 | N18: Đỗ Thị Ngọc Ánh | X18: 20234FE6010001
A19: 18 | B19: 2020606272 | C19: Vũ Tiến | D19: Huy | E19: 37557 | F19: Nam | G19: 2020DHDTTT07 | H19: Công nghệ kỹ thuật điện tử - viễn thông | I19: FE6010 | J19: K15 | K19: Thiêt kế mô hình bãi đỗ xe thông minh | L19: Khoa Điện tử | M19: 6 | N19: Đỗ Thị Ngọc Ánh | X19: 20234FE6010001
A20: 19 | B20: 2020600682 | C20: Chu Hải | D20: Đăng | E20: 37429 | F20: Nam | G20: 2020DHDTTT01 | H20: Công nghệ kỹ thuật điện tử - viễn thông | I20: FE6010 | J20: K15 | K20: Thiết kế mô hình nhà thông minh điều kiển qua app blynk | L20: Khoa Điện tử | M20: 7 | N20: Đỗ Thị Ngọc Ánh | R20: Tên đề tài do SV đề xuất. | X20: 20234FE6010001
A21: 20 | B21: 2020600597 | C21: Trần Khánh | D21: Dư | E21: 37378 | F21: Nam | G21: 2020DHDTTT01 | H21: Công nghệ kỹ thuật điện tử - viễn thông | I21: FE6010 | J21: K15 | K21: Thiết kế mô hình nhà thông minh điều kiển qua app blynk | L21: Khoa Điện tử | M21: 7 | N21: Đỗ Thị Ngọc Ánh | R21: Tên đề tài do SV đề xuất. | X21: 20234FE6010001
A22: 21 | B22: 2020600695 | C22: Đặng Văn | D22: Hiệp | E22: 37553 | F22: Nam | G22: 2020DHDTTT01 | H22: Công nghệ kỹ thuật điện tử - viễn thông | I22: FE6010 | J22: K15 | K22: Thiết kế mô hình nhà thông minh điều kiển qua app blynk | L22: Khoa Điện tử | M22: 7 | N22: Đỗ Thị Ngọc Ánh | R22: Tên đề tài do SV đề xuất. | X22: 20234FE6010001
A23: 22 | B23: 2020601393 | C23: Nguyễn Đức | D23: Duy | E23: 37559 | F23: Nam | G23: 2020DHDTTT02 | H23: Công nghệ kỹ thuật điện tử - viễn thông | I23: FE6010 | J23: K15 | K23: Thiết kế hệ thống phân loại màu sắc ứng dụng trong nông sản | L23: Khoa Điện tử | M23: 8 | N23: Lê Thị Trang | X23: 20234FE6010001
A24: 23 | B24: 2020601801 | C24: Lê Ngọc | D24: Hà | E24: 37309 | F24: Nam | G24: 2020DHDTTT02 | H24: Công nghệ kỹ thuật điện tử - viễn thông | I24: FE6010 | J24: K15 | K24: Thiết kế hệ thống phân loại màu sắc ứng dụng trong nông sản | L24: Khoa Điện tử | M24: 8 | N24: Lê Thị Trang | X24: 20234FE6010001
A25: 24 | B25: 2020601180 | C25: Nguyễn Đức | D25: Vượng | E25: 37479 | F25: Nam | G25: 2020DHDTTT02 | H25: Công nghệ kỹ thuật điện tử - viễn thông | I25: FE6010 | J25: K15 | K25: Thiết kế hệ thống phân loại màu sắc ứng dụng trong nông sản | L25: Khoa Điện tử | M25: 8 | N25: Lê Thị Trang | X25: 20234FE6010001
A26: 25 | B26: 2019608089 | C26: Nguyễn Mạnh | D26: Hải | E26: 36328 | F26: Nam | G26: LT CĐ - ĐH ĐTTT 1 | H26: Công nghệ kỹ thuật điện tử - viễn thông | I26: FE6010 | J26: K14 | K26: Thiết kế và triển khai mô hình hệ thống chiếu sáng thông minh | L26: Khoa Điện tử | M26: 9 | N26: Trương Thị Bích Liên | X26: 20234FE6010001
A27: 26 | B27: 2020603132 | C27: Nguyễn Mạnh | D27: Hùng | E27: 37516 | F27: Nam | G27: 2020DHDTTT03 | H27: Công nghệ kỹ thuật điện tử - viễn thông | I27: FE6010 | J27: K15 | K27: Thiết kế và triển khai mô hình hệ thống chiếu sáng thông minh | L27: Khoa Điện tử | M27: 9 | N27: Trương Thị Bích Liên | X27: 20234FE6010001
A28: 27 | B28: 2020605241 | C28: Nguyễn Mạnh | D28: Việt | E28: 37513 | F28: Nam | G28: 2020DHDTTT06 | H28: Công nghệ kỹ thuật điện tử - viễn thông | I28: FE6010 | J28: K15 | K28: Thiết kế và triển khai mô hình hệ thống chiếu sáng thông minh | L28: Khoa Điện tử | M28: 9 | N28: Trương Thị Bích Liên | X28: 20234FE6010001
A29: 28 | B29: 2020604003 | C29: Nguyễn Tuấn | D29: Anh | E29: 37265 | F29: Nam | G29: 2020DHDTTT04 | H29: Công nghệ kỹ thuật điện tử - viễn thông | I29: FE6010 | J29: K15 | K29: Thiết kế hệ thống cửa thông minh sử dụng công nghệ RFID | L29: Khoa Điện tử | M29: 10 | N29: Vũ Trung Kiên | X29: 20234FE6010001
A30: 29 | B30: 2020603201 | C30: Lê Đức | D30: Bình | E30: 37357 | F30: Nam | G30: 2020DHDTTT04 | H30: Công nghệ kỹ thuật điện tử - viễn thông | I30: FE6010 | J30: K15 | K30: Thiết kế hệ thống cửa thông minh sử dụng công nghệ RFID | L30: Khoa Điện tử | M30: 10 | N30: Vũ Trung Kiên | X30: 20234FE6010001
A31: 30 | B31: 2020603888 | C31: Nhâm Hùng | D31: Cường | E31: 28/06/2002 | F31: Nam | G31: 2020DHDTTT04 | H31: Công nghệ kỹ thuật điện tử - viễn thông | I31: FE6010 | J31: K15 | K31: Thiết kế hệ thống cửa thông minh sử dụng công nghệ RFID | L31: Khoa Điện tử | M31: 10 | N31: Vũ Trung Kiên | X31: 20234FE6010001
A32: 31 | B32: 2020601498 | C32: Trần Tuấn | D32: Anh | E32: 24/10/2002 | F32: Nam | G32: 2020DHDTTT02 | H32: Công nghệ kỹ thuật điện tử - viễn thông | I32: FE6010 | J32: K15 | K32: Nghiên cứu, thiết kế bộ đo kiểm và kiểm soát dữ liệu của modul cảm biến. | L32: Khoa Điện tử | M32: 11 | N32: Đinh Thị Kim Phượng | X32: 20234FE6010001
A33: 32 | B33: 2020601988 | C33: Phạm Duy | D33: Đạt | E33: 37534 | F33: Nam | G33: 2020DHDTTT02 | H33: Công nghệ kỹ thuật điện tử - viễn thông | I33: FE6010 | J33: K15 | K33: Nghiên cứu, thiết kế bộ đo kiểm và kiểm soát dữ liệu của modul cảm biến. | L33: Khoa Điện tử | M33: 11 | N33: Đinh Thị Kim Phượng | X33: 20234FE6010001
A34: 33 | B34: 2020601820 | C34: Phạm Hồng | D34: Quang | E34: 37294 | F34: Nam | G34: 2020DHDTTT02 | H34: Công nghệ kỹ thuật điện tử - viễn thông | I34: FE6010 | J34: K15 | K34: Nghiên cứu, thiết kế bộ đo kiểm và kiểm soát dữ liệu của modul cảm biến. | L34: Khoa Điện tử | M34: 11 | N34: Đinh Thị Kim Phượng | X34: 20234FE6010001
A35: 34 | B35: 2020602100 | C35: Nguyễn Thị | D35: Nhàn | E35: 37412 | F35: Nữ | G35: 2020DHDTTT02 | H35: Công nghệ kỹ thuật điện tử - viễn thông | I35: FE6010 | J35: K15 | K35: Thiết kế hệ thống vườn thông minh | L35: Khoa Điện tử | M35: 12 | N35: Hà Thị Phương | X35: 20234FE6010001
A36: 35 | B36: 2020601643 | C36: Nguyễn Văn | D36: Thành | E36: 37379 | F36: Nam | G36: 2020DHDTTT02 | H36: Công nghệ kỹ thuật điện tử - viễn thông | I36: FE6010 | J36: K15 | K36: Thiết kế hệ thống vườn thông minh | L36: Khoa Điện tử | M36: 12 | N36: Hà Thị Phương | X36: 20234FE6010001
A37: 36 | B37: 2020604515 | C37: Nguyễn Thị | D37: Tươi | E37: 37415 | F37: Nữ | G37: 2020DHDTTT05 | H37: Công nghệ kỹ thuật điện tử - viễn thông | I37: FE6010 | J37: K15 | K37: Thiết kế hệ thống vườn thông minh | L37: Khoa Điện tử | M37: 12 | N37: Hà Thị Phương | X37: 20234FE6010001
A38: 37 | B38: 2020603979 | C38: Nguyễn Khắc | D38: Cường | E38: 37609 | F38: Nam | G38: 2020DHDTTT04 | H38: Công nghệ kỹ thuật điện tử - viễn thông | I38: FE6010 | J38: K15 | K38: Nghiên cứu mạch đo kiểm soát môi trường dưới nước | L38: Khoa Điện tử | M38: 13 | N38: Bùi Thị Thu Hà | R38: Tên đề tài không phù hợp do chưa thể hiện mức độ Thiết kế theo thang Bloom | X38: 20234FE6010001
A39: 38 | B39: 2020603437 | C39: Nghiêm Đình | D39: Đạt | E39: 37454 | F39: Nam | G39: 2020DHDTTT04 | H39: Công nghệ kỹ thuật điện tử - viễn thông | I39: FE6010 | J39: K15 | K39: Nghiên cứu mạch đo kiểm soát môi trường dưới nước | L39: Khoa Điện tử | M39: 13 | N39: Bùi Thị Thu Hà | R39: Tên đề tài không phù hợp do chưa thể hiện mức độ Thiết kế theo thang Bloom | X39: 20234FE6010001
A40: 39 | B40: 2020603357 | C40: Nguyễn Xuân | D40: Sơn | E40: 37348 | F40: Nam | G40: 2020DHDTTT04 | H40: Công nghệ kỹ thuật điện tử - viễn thông | I40: FE6010 | J40: K15 | K40: Nghiên cứu mạch đo kiểm soát môi trường dưới nước | L40: Khoa Điện tử | M40: 13 | N40: Bùi Thị Thu Hà | R40: Tên đề tài không phù hợp do chưa thể hiện mức độ Thiết kế theo thang Bloom | X40: 20234FE6010001
...

Sheet Tong hop
A1: TT | B1: Học vị | C1: Họ và tên GV | D1: Tổng | E1: ĐTVT | G1: KTMT | I1: MMT&TTDL
E2: FE6010 | F2: 0803106 | G2: FE6076 | H2: 0803145 | I2: FE6102 | J2: 0803168
A3: 1 | B3: Thạc sĩ | C3: Nguyễn Ngọc Anh | D3: =COUNTIFS('DSSV-Tên đề tài-Hướng dẫn'!N:N,C3) -> 6 | E3: =COUNTIFS('DSSV-Tên đề tài-Hướng dẫn'!I:I,$E$2,'DSSV-Tên đề tài-Hướng dẫn'!N:N,C3) -> 6 | F3: =COUNTIFS('DSSV-Tên đề tài-Hướng dẫn'!I:I,$F$2,'DSSV-Tên đề tài-Hướng dẫn'!N:N,C3) -> 0 | G3: =COUNTIFS('DSSV-Tên đề tài-Hướng dẫn'!I:I,$G$2,'DSSV-Tên đề tài-Hướng dẫn'!N:N,C3) -> 0 | H3: =COUNTIFS('DSSV-Tên đề tài-Hướng dẫn'!I:I,$H$2,'DSSV-Tên đề tài-Hướng dẫn'!N:N,C3) -> 0 | I3: =COUNTIFS('DSSV-Tên đề tài-Hướng dẫn'!I:I,$I$2,'DSSV-Tên đề tài-Hướng dẫn'!N:N,C3) -> 0 | J3: =COUNTIFS('DSSV-Tên đề tài-Hướng dẫn'!I:I,$J$2,'DSSV-Tên đề tài-Hướng dẫn'!N:N,C3) -> 0 | K3: =F3+H3+J3 -> 0
A4: 2 | B4: Thạc sĩ | C4: Nguyễn Tuấn Anh | D4: =COUNTIFS('DSSV-Tên đề tài-Hướng dẫn'!N:N,C4) -> 6 | E4: =COUNTIFS('DSSV-Tên đề tài-Hướng dẫn'!I:I,$E$2,'DSSV-Tên đề tài-Hướng dẫn'!N:N,C4) -> 0 | F4: =COUNTIFS('DSSV-Tên đề tài-Hướng dẫn'!I:I,$F$2,'DSSV-Tên đề tài-Hướng dẫn'!N:N,C4) -> 0 | G4: =COUNTIFS('DSSV-Tên đề tài-Hướng dẫn'!I:I,$G$2,'DSSV-Tên đề tài-Hướng dẫn'!N:N,C4) -> 3 | H4: =COUNTIFS('DSSV-Tên đề tài-Hướng dẫn'!I:I,$H$2,'DSSV-Tên đề tài-Hướng dẫn'!N:N,C4) -> 3 | I4: =COUNTIFS('DSSV-Tên đề tài-Hướng dẫn'!I:I,$I$2,'DSSV-Tên đề tài-Hướng dẫn'!N:N,C4) -> 0 | J4: =COUNTIFS('DSSV-Tên đề tài-Hướng dẫn'!I:I,$J$2,'DSSV-Tên đề tài-Hướng dẫn'!N:N,C4) -> 0 | K4: =F4+H4+J4 -> 3
A5: 3 | B5: Thạc sĩ | C5: Đỗ Thị Ngọc Ánh | D5: =COUNTIFS('DSSV-Tên đề tài-Hướng dẫn'!N:N,C5) -> 6 | E5: =COUNTIFS('DSSV-Tên đề tài-Hướng dẫn'!I:I,$E$2,'DSSV-Tên đề tài-Hướng dẫn'!N:N,C5) -> 6 | F5: =COUNTIFS('DSSV-Tên đề tài-Hướng dẫn'!I:I,$F$2,'DSSV-Tên đề tài-Hướng dẫn'!N:N,C5) -> 0 | G5: =COUNTIFS('DSSV-Tên đề tài-Hướng dẫn'!I:I,$G$2,'DSSV-Tên đề tài-Hướng dẫn'!N:N,C5) -> 0 | H5: =COUNTIFS('DSSV-Tên đề tài-Hướng dẫn'!I:I,$H$2,'DSSV-Tên đề tài-Hướng dẫn'!N:N,C5) -> 0 | I5: =COUNTIFS('DSSV-Tên đề tài-Hướng dẫn'!I:I,$I$2,'DSSV-Tên đề tài-Hướng dẫn'!N:N,C5) -> 0 | J5: =COUNTIFS('DSSV-Tên đề tài-Hướng dẫn'!I:I,$J$2,'DSSV-Tên đề tài-Hướng dẫn'!N:N,C5) -> 0 | K5: =F5+H5+J5 -> 0
A6: 4 | B6: Tiến sĩ | C6: Bồ Quốc Bảo | D6: =COUNTIFS('DSSV-Tên đề tài-Hướng dẫn'!N:N,C6) -> 6 | E6: =COUNTIFS('DSSV-Tên đề tài-Hướng dẫn'!I:I,$E$2,'DSSV-Tên đề tài-Hướng dẫn'!N:N,C6) -> 6 | F6: =COUNTIFS('DSSV-Tên đề tài-Hướng dẫn'!I:I,$F$2,'DSSV-Tên đề tài-Hướng dẫn'!N:N,C6) -> 0 | G6: =COUNTIFS('DSSV-Tên đề tài-Hướng dẫn'!I:I,$G$2,'DSSV-Tên đề tài-Hướng dẫn'!N:N,C6) -> 0 | H6: =COUNTIFS('DSSV-Tên đề tài-Hướng dẫn'!I:I,$H$2,'DSSV-Tên đề tài-Hướng dẫn'!N:N,C6) -> 0 | I6: =COUNTIFS('DSSV-Tên đề tài-Hướng dẫn'!I:I,$I$2,'DSSV-Tên đề tài-Hướng dẫn'!N:N,C6) -> 0 | J6: =COUNTIFS('DSSV-Tên đề tài-Hướng dẫn'!I:I,$J$2,'DSSV-Tên đề tài-Hướng dẫn'!N:N,C6) -> 0 | K6: =F6+H6+J6 -> 0
A7: 5 | B7: Thạc sĩ | C7: Phạm Văn Chiến | D7: =COUNTIFS('DSSV-Tên đề tài-Hướng dẫn'!N:N,C7) -> 3 | E7: =COUNTIFS('DSSV-Tên đề tài-Hướng dẫn'!I:I,$E$2,'DSSV-Tên đề tài-Hướng dẫn'!N:N,C7) -> 0 | F7: =COUNTIFS('DSSV-Tên đề tài-Hướng dẫn'!I:I,$F$2,'DSSV-Tên đề tài-Hướng dẫn'!N:N,C7) -> 0 | G7: =COUNTIFS('DSSV-Tên đề tài-Hướng dẫn'!I:I,$G$2,'DSSV-Tên đề tài-Hướng dẫn'!N:N,C7) -> 3 | H7: =COUNTIFS('DSSV-Tên đề tài-Hướng dẫn'!I:I,$H$2,'DSSV-Tên đề tài-Hướng dẫn'!N:N,C7) -> 0 | I7: =COUNTIFS('DSSV-Tên đề tài-Hướng dẫn'!I:I,$I$2,'DSSV-Tên đề tài-Hướng dẫn'!N:N,C7) -> 0 | J7: =COUNTIFS('DSSV-Tên đề tài-Hướng dẫn'!I:I,$J$2,'DSSV-Tên đề tài-Hướng dẫn'!N:N,C7) -> 0 | K7: =F7+H7+J7 -> 0
A8: 6 | B8: Thạc sĩ | C8: Nguyễn Văn Cường | D8: =COUNTIFS('DSSV-Tên đề tài-Hướng dẫn'!N:N,C8) -> 0 | E8: =COUNTIFS('DSSV-Tên đề tài-Hướng dẫn'!I:I,$E$2,'DSSV-Tên đề tài-Hướng dẫn'!N:N,C8) -> 0 | F8: =COUNTIFS('DSSV-Tên đề tài-Hướng dẫn'!I:I,$F$2,'DSSV-Tên đề tài-Hướng dẫn'!N:N,C8) -> 0 | G8: =COUNTIFS('DSSV-Tên đề tài-Hướng dẫn'!I:I,$G$2,'DSSV-Tên đề tài-Hướng dẫn'!N:N,C8) -> 0 | H8: =COUNTIFS('DSSV-Tên đề tài-Hướng dẫn'!I:I,$H$2,'DSSV-Tên đề tài-Hướng dẫn'!N:N,C8) -> 0 | I8: =COUNTIFS('DSSV-Tên đề tài-Hướng dẫn'!I:I,$I$2,'DSSV-Tên đề tài-Hướng dẫn'!N:N,C8) -> 0 | J8: =COUNTIFS('DSSV-Tên đề tài-Hướng dẫn'!I:I,$J$2,'DSSV-Tên đề tài-Hướng dẫn'!N:N,C8) -> 0 | K8: =F8+H8+J8 -> 0
A9: 7 | B9: Thạc sĩ | C9: Nguyễn Anh Dũng | D9: =COUNTIFS('DSSV-Tên đề tài-Hướng dẫn'!N:N,C9) -> 6 | E9: =COUNTIFS('DSSV-Tên đề tài-Hướng dẫn'!I:I,$E$2,'DSSV-Tên đề tài-Hướng dẫn'!N:N,C9) -> 6 | F9: =COUNTIFS('DSSV-Tên đề tài-Hướng dẫn'!I:I,$F$2,'DSSV-Tên đề tài-Hướng dẫn'!N:N,C9) -> 0 | G9: =COUNTIFS('DSSV-Tên đề tài-Hướng dẫn'!I:I,$G$2,'DSSV-Tên đề tài-Hướng dẫn'!N:N,C9) -> 0 | H9: =COUNTIFS('DSSV-Tên đề tài-Hướng dẫn'!I:I,$H$2,'DSSV-Tên đề tài-Hướng dẫn'!N:N,C9) -> 0 | I9: =COUNTIFS('DSSV-Tên đề tài-Hướng dẫn'!I:I,$I$2,'DSSV-Tên đề tài-Hướng dẫn'!N:N,C9) -> 0 | J9: =COUNTIFS('DSSV-Tên đề tài-Hướng dẫn'!I:I,$J$2,'DSSV-Tên đề tài-Hướng dẫn'!N:N,C9) -> 0 | K9: =F9+H9+J9 -> 0
A10: 8 | B10: Thạc sĩ | C10: Nguyễn Văn Dũng | D10: =COUNTIFS('DSSV-Tên đề tài-Hướng dẫn'!N:N,C10) -> 3 | E10: =COUNTIFS('DSSV-Tên đề tài-Hướng dẫn'!I:I,$E$2,'DSSV-Tên đề tài-Hướng dẫn'!N:N,C10) -> 3 | F10: =COUNTIFS('DSSV-Tên đề tài-Hướng dẫn'!I:I,$F$2,'DSSV-Tên đề tài-Hướng dẫn'!N:N,C10) -> 0 | G10: =COUNTIFS('DSSV-Tên đề tài-Hướng dẫn'!I:I,$G$2,'DSSV-Tên đề tài-Hướng dẫn'!N:N,C10) -> 0 | H10: =COUNTIFS('DSSV-Tên đề tài-Hướng dẫn'!I:I,$H$2,'DSSV-Tên đề tài-Hướng dẫn'!N:N,C10) -> 0 | I10: =COUNTIFS('DSSV-Tên đề tài-Hướng dẫn'!I:I,$I$2,'DSSV-Tên đề tài-Hướng dẫn'!N:N,C10) -> 0 | J10: =COUNTIFS('DSSV-Tên đề tài-Hướng dẫn'!I:I,$J$2,'DSSV-Tên đề tài-Hướng dẫn'!N:N,C10) -> 0 | K10: =F10+H10+J10 -> 0
A11: 9 | B11: Tiến sĩ | C11: Hà Thị Kim Duyên | D11: =COUNTIFS('DSSV-Tên đề tài-Hướng dẫn'!N:N,C11) -> 6 | E11: =COUNTIFS('DSSV-Tên đề tài-Hướng dẫn'!I:I,$E$2,'DSSV-Tên đề tài-Hướng dẫn'!N:N,C11) -> 6 | F11: =COUNTIFS('DSSV-Tên đề tài-Hướng dẫn'!I:I,$F$2,'DSSV-Tên đề tài-Hướng dẫn'!N:N,C11) -> 0 | G11: =COUNTIFS('DSSV-Tên đề tài-Hướng dẫn'!I:I,$G$2,'DSSV-Tên đề tài-Hướng dẫn'!N:N,C11) -> 0 | H11: =COUNTIFS('DSSV-Tên đề tài-Hướng dẫn'!I:I,$H$2,'DSSV-Tên đề tài-Hướng dẫn'!N:N,C11) -> 0 | I11: =COUNTIFS('DSSV-Tên đề tài-Hướng dẫn'!I:I,$I$2,'DSSV-Tên đề tài-Hướng dẫn'!N:N,C11) -> 0 | J11: =COUNTIFS('DSSV-Tên đề tài-Hướng dẫn'!I:I,$J$2,'DSSV-Tên đề tài-Hướng dẫn'!N:N,C11) -> 0 | K11: =F11+H11+J11 -> 0
A12: 10 | B12: Thạc sĩ | C12: Bùi Thị Thu Hà | D12: =COUNTIFS('DSSV-Tên đề tài-Hướng dẫn'!N:N,C12) -> 6 | E12: =COUNTIFS('DSSV-Tên đề tài-Hướng dẫn'!I:I,$E$2,'DSSV-Tên đề tài-Hướng dẫn'!N:N,C12) -> 6 | F12: =COUNTIFS('DSSV-Tên đề tài-Hướng dẫn'!I:I,$F$2,'DSSV-Tên đề tài-Hướng dẫn'!N:N,C12) -> 0 | G12: =COUNTIFS('DSSV-Tên đề tài-Hướng dẫn'!I:I,$G$2,'DSSV-Tên đề tài-Hướng dẫn'!N:N,C12) -> 0 | H12: =COUNTIFS('DSSV-Tên đề tài-Hướng dẫn'!I:I,$H$2,'DSSV-Tên đề tài-Hướng dẫn'!N:N,C12) -> 0 | I12: =COUNTIFS('DSSV-Tên đề tài-Hướng dẫn'!I:I,$I$2,'DSSV-Tên đề tài-Hướng dẫn'!N:N,C12) -> 0 | J12: =COUNTIFS('DSSV-Tên đề tài-Hướng dẫn'!I:I,$J$2,'DSSV-Tên đề tài-Hướng dẫn'!N:N,C12) -> 0 | K12: =F12+H12+J12 -> 0
A13: 11 | B13: Thạc sĩ | C13: Nguyễn Thị Thu Hà | D13: =COUNTIFS('DSSV-Tên đề tài-Hướng dẫn'!N:N,C13) -> 6 | E13: =COUNTIFS('DSSV-Tên đề tài-Hướng dẫn'!I:I,$E$2,'DSSV-Tên đề tài-Hướng dẫn'!N:N,C13) -> 6 | F13: =COUNTIFS('DSSV-Tên đề tài-Hướng dẫn'!I:I,$F$2,'DSSV-Tên đề tài-Hướng dẫn'!N:N,C13) -> 0 | G13: =COUNTIFS('DSSV-Tên đề tài-Hướng dẫn'!I:I,$G$2,'DSSV-Tên đề tài-Hướng dẫn'!N:N,C13) -> 0 | H13: =COUNTIFS('DSSV-Tên đề tài-Hướng dẫn'!I:I,$H$2,'DSSV-Tên đề tài-Hướng dẫn'!N:N,C13) -> 0 | I13: =COUNTIFS('DSSV-Tên đề tài-Hướng dẫn'!I:I,$I$2,'DSSV-Tên đề tài-Hướng dẫn'!N:N,C13) -> 0 | J13: =COUNTIFS('DSSV-Tên đề tài-Hướng dẫn'!I:I,$J$2,'DSSV-Tên đề tài-Hướng dẫn'!N:N,C13) -> 0 | K13: =F13+H13+J13 -> 0
A14: 12 | B14: Tiến sĩ | C14: Nguyễn Đắc Hải | D14: =COUNTIFS('DSSV-Tên đề tài-Hướng dẫn'!N:N,C14) -> 6 | E14: =COUNTIFS('DSSV-Tên đề tài-Hướng dẫn'!I:I,$E$2,'DSSV-Tên đề tài-Hướng dẫn'!N:N,C14) -> 6 | F14: =COUNTIFS('DSSV-Tên đề tài-Hướng dẫn'!I:I,$F$2,'DSSV-Tên đề tài-Hướng dẫn'!N:N,C14) -> 0 | G14: =COUNTIFS('DSSV-Tên đề tài-Hướng dẫn'!I:I,$G$2,'DSSV-Tên đề tài-Hướng dẫn'!N:N,C14) -> 0 | H14: =COUNTIFS('DSSV-Tên đề tài-Hướng dẫn'!I:I,$H$2,'DSSV-Tên đề tài-Hướng dẫn'!N:N,C14) -> 0 | I14: =COUNTIFS('DSSV-Tên đề tài-Hướng dẫn'!I:I,$I$2,'DSSV-Tên đề tài-Hướng dẫn'!N:N,C14) -> 0 | J14: =COUNTIFS('DSSV-Tên đề tài-Hướng dẫn'!I:I,$J$2,'DSSV-Tên đề tài-Hướng dẫn'!N:N,C14) -> 0 | K14: =F14+H14+J14 -> 0
... A50: 48 | B50: Tiến sĩ | C50: Kiều Xuân Thực | D50: =COUNTIFS('DSSV-Tên đề tài-Hướng dẫn'!N:N,C50) -> 0 | E50: =COUNTIFS('DSSV-Tên đề tài-Hướng dẫn'!I:I,$E$2,'DSSV-Tên đề tài-Hướng dẫn'!N:N,C50) -> 0 | F50: =COUNTIFS('DSSV-Tên đề tài-Hướng dẫn'!I:I,$F$2,'DSSV-Tên đề tài-Hướng dẫn'!N:N,C50) -> 0 | G50: =COUNTIFS('DSSV-Tên đề tài-Hướng dẫn'!I:I,$G$2,'DSSV-Tên đề tài-Hướng dẫn'!N:N,C50) -> 0 | H50: =COUNTIFS('DSSV-Tên đề tài-Hướng dẫn'!I:I,$H$2,'DSSV-Tên đề tài-Hướng dẫn'!N:N,C50) -> 0 | I50: =COUNTIFS('DSSV-Tên đề tài-Hướng dẫn'!I:I,$I$2,'DSSV-Tên đề tài-Hướng dẫn'!N:N,C50) -> 0 | J50: =COUNTIFS('DSSV-Tên đề tài-Hướng dẫn'!I:I,$J$2,'DSSV-Tên đề tài-Hướng dẫn'!N:N,C50) -> 0 | K50: =F50+H50+J50 -> 0
C53: N/A | D53: =SUM(D3:D50) -> 228 | E53: =SUM(E3:E50) -> 168 | F53: =SUM(F3:F50) -> 3 | G53: =SUM(G3:G50) -> 31 | H53: =SUM(H3:H50) -> 5 | I53: =SUM(I3:I50) -> 18 | J53: =SUM(J3:J50) -> 3
D54: =COUNTIFS('[2]Danh sach SV thuc hien DATN'!$N$32:$N$61,0) -> #VALUE! | E54: =COUNTIFS('[2]Danh sach SV thuc hien DATN'!$N$32:$N$61,0,'[2]Danh sach SV thuc hien DATN'!$G$32:$G$61,$E$2) -> #VALUE! | F54: =COUNTIFS('[2]Danh sach SV thuc hien DATN'!$N$32:$N$61,0,'[2]Danh sach SV thuc hien DATN'!$G$32:$G$61,$F$2) -> #VALUE! | H54: =COUNTIFS('[2]Danh sach SV thuc hien DATN'!$N$32:$N$61,0,'[2]Danh sach SV thuc hien DATN'!$G$32:$G$61,$H$2) -> #VALUE! | J54: =COUNTIFS('[2]Danh sach SV thuc hien DATN'!$N$32:$N$61,0,'[2]Danh sach SV thuc hien DATN'!$G$32:$G$61,$J$2) -> #VALUE!
